<?xml version="1.0" ?>
<!-- =================================================================================== -->
<!-- |    This document was autogenerated by xacro from /Users/jaimemcmf/Developer/thesis/edhmor_genesis/urdf/modular_robot.urdf.xacro | -->
<!-- |    EDITING THIS FILE BY HAND IS NOT RECOMMENDED                                 | -->
<!-- =================================================================================== -->
<robot name="modular_robot">
  <!-- <xacro:emerge_module name="emerge_plus"/> -->
  <link name="flat_base_link">
    <inertial>
      <origin rpy="0 0 0" xyz="0 0 0"/>
      <mass value="0.65"/>
      <inertia ixx="0.0013730107369875001" ixy="0.0" ixz="0.0" iyy="0.0013730107369875001" iyz="0.0" izz="0.0024180390000000003"/>
    </inertial>
    <visual>
      <origin rpy="0 0 0" xyz="0 0 0"/>
      <geometry>
        <box size="0.0747 0.0747 0.0275115"/>
      </geometry>
      <material name="grey">
        <color rgba="0.7 0.7 0.7 1.0"/>
      </material>
    </visual>
    <collision>
      <origin rpy="0 0 0" xyz="0 0 0"/>
      <geometry>
        <box size="0.1494 0.1494 0.055023"/>
      </geometry>
    </collision>
  </link>
  <link name="emerge_plus_connector_link">
    <visual>
      <origin rpy="0 0 0" xyz="0 0 0"/>
      <geometry>
        <box size="0.0385 0.0305 0.0275"/>
      </geometry>
      <material name="orange">
        <color rgba="1 0.4 0 1"/>
      </material>
    </visual>
    <collision>
      <origin rpy="0 0 0" xyz="0 0 0"/>
      <geometry>
        <box size="0.0385 0.0305 0.0275"/>
      </geometry>
    </collision>
    <inertial>
      <origin rpy="0 0 0" xyz="0 0 0"/>
      <mass value="0.06"/>
      <inertia ixx="0.00006" ixy="0" ixz="0" iyy="0.00005" iyz="0" izz="0.00007"/>
    </inertial>
  </link>
  <link name="emerge_plus_motor_link">
    <visual>
      <origin rpy="0 0 0" xyz="0 0 0"/>
      <geometry>
        <box size="0.048125 0.038125 0.034375"/>
      </geometry>
      <material name="orange">
        <color rgba="1 0.4 0 1"/>
      </material>
    </visual>
    <collision>
      <origin rpy="0 0 0" xyz="0 0 0"/>
      <geometry>
        <box size="0.048125 0.038125 0.034375"/>
      </geometry>
    </collision>
    <inertial>
      <origin rpy="0 0 0" xyz="0 0 0"/>
      <mass value="0.06"/>
      <inertia ixx="0.00006" ixy="0" ixz="0" iyy="0.00005" iyz="0" izz="0.00007"/>
    </inertial>
  </link>
  <joint name="emerge_plus_joint" type="revolute">
    <parent link="emerge_plus_connector_link"/>
    <child link="emerge_plus_motor_link"/>
    <origin rpy="0 0 0" xyz="0.03 0 0"/>
    <axis xyz="0 1 0"/>
    <!-- <limit effort="0.5" velocity="2.0" lower="-0.12" upper="0.12" /> -->
    <limit effort="0.5" lower="-0.6" upper="0.6" velocity="2.0"/>
  </joint>
  <link name="emerge_minus_connector_link">
    <visual>
      <origin rpy="0 0 0" xyz="0 0 0"/>
      <geometry>
        <box size="0.0385 0.0305 0.0275"/>
      </geometry>
      <material name="orange">
        <color rgba="1 0.4 0 1"/>
      </material>
    </visual>
    <collision>
      <origin rpy="0 0 0" xyz="0 0 0"/>
      <geometry>
        <box size="0.0385 0.0305 0.0275"/>
      </geometry>
    </collision>
    <inertial>
      <origin rpy="0 0 0" xyz="0 0 0"/>
      <mass value="0.06"/>
      <inertia ixx="0.00006" ixy="0" ixz="0" iyy="0.00005" iyz="0" izz="0.00007"/>
    </inertial>
  </link>
  <link name="emerge_minus_motor_link">
    <visual>
      <origin rpy="0 0 0" xyz="0 0 0"/>
      <geometry>
        <box size="0.048125 0.038125 0.034375"/>
      </geometry>
      <material name="orange">
        <color rgba="1 0.4 0 1"/>
      </material>
    </visual>
    <collision>
      <origin rpy="0 0 0" xyz="0 0 0"/>
      <geometry>
        <box size="0.048125 0.038125 0.034375"/>
      </geometry>
    </collision>
    <inertial>
      <origin rpy="0 0 0" xyz="0 0 0"/>
      <mass value="0.06"/>
      <inertia ixx="0.00006" ixy="0" ixz="0" iyy="0.00005" iyz="0" izz="0.00007"/>
    </inertial>
  </link>
  <joint name="emerge_minus_joint" type="revolute">
    <parent link="emerge_minus_connector_link"/>
    <child link="emerge_minus_motor_link"/>
    <origin rpy="0 0 0" xyz="0.03 0 0"/>
    <axis xyz="0 1 0"/>
    <!-- <limit effort="0.5" velocity="2.0" lower="-0.12" upper="0.12" /> -->
    <limit effort="0.5" lower="-0.6" upper="0.6" velocity="2.0"/>
  </joint>
  <!-- +X side -->
  <joint name="joint_x_plus" type="revolute">
    <parent link="flat_base_link"/>
    <child link="emerge_plus_connector_link"/>
    <origin rpy="0 0 0" xyz="0.0526 0 0"/>
    <axis xyz="0 1 0"/>
    <limit effort="10" lower="-1.57" upper="1.57" velocity="3"/>
  </joint>
  <!-- -X side -->
  <joint name="joint_x_minus" type="revolute">
    <parent link="flat_base_link"/>
    <child link="emerge_minus_connector_link"/>
    <origin rpy="0 0 3.141592653589793" xyz="-0.0526 0 0"/>
    <axis xyz="0 1 0"/>
    <limit effort="10" lower="-1.57" upper="1.57" velocity="3"/>
  </joint>
</robot>
